Workbook

Sheet README
A1: GAME DATA TEMPLATE — The Last Blessing
A2: Purpose | B2: All class and skill box data from Idle_Stat_Sources, restructured as flat named-column tables for Claude Code to convert to JSON.
A3: Progression model | B3: SWG-style SP box system. Players spend Learning Points (LP) to unlock skill boxes. Each class has 4 skill branch groups (I–IV tiers each) + a Novice box + a Master capstone. Unlocking enough boxes in a prereq class opens the next tier class.
A4: Classes sheet | B4: 32 classes across base → advanced → master tiers. prereq_class links the unlock chain.
A5: SkillBoxes sheet | B5: 576 boxes. box_code encodes branch position: prefix + xooo = branch 1 active, oxoo = branch 2, etc. Tiers I–IV per branch. Stat bonuses from your Idle_Stat_Sources sheet — NOT YET BALANCED (your note). Each box has an associated "learning points (LP)" cost.
A6: ClassPromotionRules | B6: Promotion rules based on the prereq_class field in the data. Required boxes per promotion listed under boxes_required.
A7: Sheet list | B7: README | Classes | Species | SkillBoxes | Skills | Skill_Effects | ClassPromotionRules | Stats | Elements | Weapon_Types | Weapons | Gear_Types | GearSets | GearSet_Bonuses | CombatLevelFormula

Sheet Classes
A1: One row per class. tier: base=500 SP pool | advanced=750 | master=1000. prereq_class = the class that must be completed first. stat columns = cumulative totals across all boxes (from your Idle_Stat_Sources data).
A2: id | B2: name | C2: tier | D2: class_type | E2: weight | F2: dmg_type1 | G2: dmg_type2 | H2: weapon | I2: prereq_class | J2: total_HP | K2: total_SP | L2: total_TP | M2: total_MP | N2: notes
A3: 0 | B3: Blade Brandier | C3: base | D3: Melee Physical | E3: Heavy | F3: Slashing | G3: Piercing | H3: Blade | J3: 100 | K3: 136 | L3: 123 | M3: 0
A4: 1 | B4: Twin Blade | C4: base | D4: Melee Physical | E4: Medium | F4: Slashing | G4: Cursing | H4: Twin Blades | J4: 204 | K4: 89 | L4: 89 | M4: 9
A5: 2 | B5: Wave User | C5: base | D5: Melee Magical | E5: Light | F5: Arcane | G5: Support | H5: Focus | J5: 154 | K5: 50 | L5: 13 | M5: 166
A6: 3 | B6: Harvest Cleric | C6: base | D6: Ranged Magical | E6: Light | F6: Arcane | G6: Relic | H6: Wand | J6: 166 | K6: 57 | L6: 19 | M6: 112
A7: 4 | B7: Guard Knight | C7: advanced | D7: Melee Physical | E7: Heavy | F7: Slashing | G7: Piercing | H7: Long Blade | I7: Blade Brandier | J7: 347 | K7: 29 | L7: 101 | M7: 0
A8: 5 | B8: Branded Barbarian | C8: advanced | D8: Melee Physical | E8: Heavy | F8: Slashing | G8: Blunt | H8: Heavy Ax | I8: Blade Brandier | J8: 244 | K8: 73 | L8: 72 | M8: 0
A9: 6 | B9: Curse Knight | C9: advanced | D9: Melee Magical | E9: Heavy | F9: Piercing | G9: Relic | H9: Cursed Blade | I9: Blade Brandier | J9: 180 | K9: 55 | L9: 20 | M9: 76
A10: 7 | B10: Acro Archer | C10: advanced | D10: Ranged Physical | E10: Medum | F10: Piercing | G10: Support | H10: Bow | I10: Twin Blade | J10: 172 | K10: 73 | L10: 51 | M10: 49
A11: 8 | B11: Pistol Ranger | C11: advanced | D11: Ranged Physical | E11: Medium | F11: Piercing | G11: Cursing | H11: Dual Guns | I11: Twin Blade | J11: 172 | K11: 73 | L11: 67 | M11: 37
A12: 9 | B12: Umbral Assassin | C12: advanced | D12: Melee Physical | E12: Medium | F12: Slashing | G12: Relic | H12: Claws | I12: Twin Blade | J12: 172 | K12: 69 | L12: 63 | M12: 34
A13: 10 | B13: Arcane Wavemaster | C13: advanced | D13: Ranged Physical | E13: Medium | F13: Support | G13: Arcane | H13: Staff | I13: Wave User | J13: 160 | K13: 58 | L13: 19 | M13: 158
A14: 11 | B14: Tome Summoner | C14: advanced | D14: Ranged Magical | E14: Light | F14: Arcane | G14: Relic | H14: Runes | I14: Wave User | J14: 164 | K14: 58 | L14: 8 | M14: 148
A15: 12 | B15: Aura Priest | C15: advanced | D15: Ranged Magical | E15: Light | F15: Arcane | G15: Cursing | H15: Tome | I15: Harvest Cleric | J15: 174 | K15: 54 | L15: 8 | M15: 136
A16: 13 | B16: Martial Monk | C16: advanced | D16: Ranged Physical | E16: Light | F16: Blunt | G16: Cursing | H16: Bo Staff | I16: Harvest Cleric | J16: 192 | K16: 75 | L16: 69 | M16: 65
A17: 14 | B17: Runic Paladin | C17: master | D17: Melee Physical | E17: Heavy | F17: Blunt | G17: Support | H17: Shield | I17: Guard Knight | J17: 284 | K17: 70 | L17: 48 | M17: 22
A18: 15 | B18: Long Arm | C18: master | D18: Ranged Physical | E18: Heavy | F18: Piercing | G18: Slashing | H18: Spear | I18: Guard Knight | J18: 228 | K18: 62 | L18: 88 | M18: 18
... A34: 31 | B34: Macabre Dancer | C34: master | D34: Melee Magical | E34: Light | F34: Slashing | G34: Cursing | H34: Bladed Fans | I34: Martial Monk | J34: 188 | K34: 78 | L34: 62 | M34: 126

Sheet Species
A1: One row per species/sub-race. banned_classes: comma-separated class names. stat_mod columns: positive or negative number added to base stat.
A2: id | B2: being | C2: sub_race | D2: faction | E2: primary_stat | F2: secondary_stat | G2: banned_classes | H2: HP_mod | I2: SP_mod | J2: TP_mod | K2: MP_mod | L2: notes
A3: 0 | B3: Elf | C3: Fole | D3: Briar Collective | E3: SP | F3: MATK | G3: Guard Knight | H3: 5 | I3: 0 | J3: 0 | K3: 0
A4: 1 | B4: Elf | C4: Nume | D4: Sylvan Collective | E4: SP | F4: PATK | G4: Branded Barbarian | H4: -5 | I4: 0 | J4: 0 | K4: 5
A5: 2 | B5: Human | C5: Kkyn | D5: Steel Clan | E5: PDEF | F5: MEVA | H5: 10 | I5: 0 | J5: 5 | K5: 0
A6: 3 | B6: Human | C6: Oeld | D6: Oak Clan | E6: PDEF | F6: PEVA | H6: 0 | I6: 0 | J6: 0 | K6: 10
A7: 4 | B7: Beast | C7: Tamo | D7: Paw Tribe | E7: HP | F7: MHIT | G7: Tome Summoner | H7: 15 | I7: 0 | J7: 0 | K7: 0
A8: 5 | B8: Beast | C8: Wyld | D8: Fang Tribe | E8: HP | F8: PHIT | G8: Aura Priest | H8: 5 | I8: 5 | J8: 0 | K8: 0

Sheet SkillBoxes
A1: One row per skill box. box_code encodes structure: 2-char class prefix + branch pattern (x=active branch, o=inactive) + roman tier (I-IV), OR Novice/Master. branch_pos: 1-4=which of the 4 skill groups, 0=Novice, 5=Master. Stat bonuses sourced from Idle_Stat_Sources — not yet balanced per your notes.
A2: id | B2: class_id | C2: class_name | D2: box_name | E2: box_group | F2: box_code | G2: box_type | H2: branch_pos | I2: box_tier | J2: lp_cost | K2: cp_earned | L2: required_exp | M2: certificate_unlocked | N2: HP | O2: SP | P2: TP | Q2: MP | R2: PATK | S2: PDEF | T2: PHIT | U2: PEVA | V2: MATK | W2: MDEF | X2: MHIT | Y2: MEVA | Z2: FIR | AA2: WTR | AB2: AIR | AC2: ERT | AD2: LGT | AE2: DRK | AF2: notes
A3: 0 | B3: 0 | C3: Blade Brandier | D3: Novice Blade Brandier | F3: BBNovice | G3: novice | H3: 0 | I3: 0 | J3: 5 | K3: 25 | M3: Blade_License | O3: 14 | P3: 7 | R3: 4 | S3: 1 | T3: 3 | U3: 1
A4: 1 | B4: 0 | C4: Blade Brandier | D4: Sword Handling I | E4: Sword Handling | F4: BBxoooI | G4: skill | H4: 1 | I4: 1 | J4: 2 | K4: 10 | O4: 4 | P4: 4 | R4: 1 | S4: 1 | T4: 3 | U4: 1 | X4: 1
A5: 2 | B5: 0 | C5: Blade Brandier | D5: Sword Handling II | F5: BBxoooII | G5: skill | H5: 1 | I5: 2 | J5: 3 | K5: 10 | O5: 4 | P5: 6 | R5: 3 | S5: 1 | T5: 3 | U5: 1 | X5: 1 | Y5: 1 | AB5: 1
A6: 3 | B6: 0 | C6: Blade Brandier | D6: Sword Handling III | F6: BBxoooIII | G6: skill | H6: 1 | I6: 3 | J6: 4 | K6: 10 | N6: 7 | O6: 6 | P6: 7 | R6: 3 | S6: 3 | T6: 4 | U6: 3 | W6: 1 | X6: 1 | Y6: 1 | AB6: 1 | AD6: 1
A7: 4 | B7: 0 | C7: Blade Brandier | D7: Sword Handling IV | F7: BBxoooIV | G7: skill | H7: 1 | I7: 4 | J7: 5 | K7: 10 | N7: 7 | O7: 7 | P7: 9 | R7: 4 | S7: 3 | T7: 6 | U7: 3 | W7: 1 | X7: 3 | Y7: 3 | AB7: 1 | AD7: 1
A8: 5 | B8: 0 | C8: Blade Brandier | D8: Sword Techniques I | E8: Sword Techniques | F8: BBoxooI | G8: skill | H8: 2 | I8: 1 | J8: 2 | K8: 10 | O8: 6 | P8: 6 | R8: 3 | S8: 1 | T8: 1 | U8: 1 | W8: 1
A9: 6 | B9: 0 | C9: Blade Brandier | D9: Sword Techniques II | F9: BBoxooII | G9: skill | H9: 2 | I9: 2 | J9: 3 | K9: 10 | O9: 7 | P9: 7 | R9: 4 | S9: 1 | T9: 1 | U9: 1 | W9: 1 | Y9: 1
A10: 7 | B10: 0 | C10: Blade Brandier | D10: Sword Techniques III | F10: BBoxooIII | G10: skill | H10: 2 | I10: 3 | J10: 4 | K10: 10 | N10: 7 | O10: 9 | P10: 9 | R10: 4 | S10: 3 | T10: 2 | U10: 2 | W10: 1 | Y10: 1
A11: 8 | B11: 0 | C11: Blade Brandier | D11: Sword Techniques IV | F11: BBoxooIV | G11: skill | H11: 2 | I11: 4 | J11: 5 | K11: 10 | N11: 7 | O11: 10 | P11: 10 | R11: 6 | S11: 3 | T11: 2 | U11: 2 | W11: 1 | Y11: 1
A12: 9 | B12: 0 | C12: Blade Brandier | D12: Sword Arts I | E12: Sword Arts | F12: BBooxoI | G12: skill | H12: 3 | I12: 1 | J12: 2 | K12: 10 | O12: 6 | P12: 4 | R12: 4 | S12: 2 | T12: 2 | U12: 2 | W12: 1 | X12: 1
A13: 10 | B13: 0 | C13: Blade Brandier | D13: Sword Arts II | F13: BBooxoII | G13: skill | H13: 3 | I13: 2 | J13: 3 | K13: 10 | O13: 7 | P13: 5 | R13: 4 | S13: 2 | T13: 2 | U13: 2 | W13: 1 | X13: 1
A14: 11 | B14: 0 | C14: Blade Brandier | D14: Sword Arts III | F14: BBooxoIII | G14: skill | H14: 3 | I14: 3 | J14: 4 | K14: 10 | N14: 7 | O14: 9 | P14: 6 | R14: 6 | S14: 2 | T14: 3 | U14: 2 | W14: 1 | X14: 1
A15: 12 | B15: 0 | C15: Blade Brandier | D15: Sword Arts IV | F15: BBooxoIV | G15: skill | H15: 3 | I15: 4 | J15: 5 | K15: 10 | N15: 7 | O15: 10 | P15: 7 | R15: 6 | S15: 2 | T15: 3 | U15: 2 | W15: 1 | X15: 1
A16: 13 | B16: 0 | C16: Blade Brandier | D16: Slashing Blade I | E16: Slashing Blade | F16: BBoooxI | G16: skill | H16: 4 | I16: 1 | J16: 2 | K16: 10 | N16: 7 | O16: 6 | P16: 5 | R16: 4 | S16: 2 | T16: 3 | U16: 3 | AB16: 1
A17: 14 | B17: 0 | C17: Blade Brandier | D17: Slashing Blade II | F17: BBoooxII | G17: skill | H17: 4 | I17: 2 | J17: 3 | K17: 10 | N17: 7 | O17: 6 | P17: 6 | R17: 4 | S17: 2 | T17: 3 | U17: 3 | AB17: 1
A18: 15 | B18: 0 | C18: Blade Brandier | D18: Slashing Blade III | F18: BBoooxIII | G18: skill | H18: 4 | I18: 3 | J18: 4 | K18: 10 | N18: 11 | O18: 7 | P18: 7 | R18: 6 | S18: 2 | T18: 4 | U18: 3 | X18: 1 | AB18: 1 | AD18: 1
A19: 16 | B19: 0 | C19: Blade Brandier | D19: Slashing Blade IV | F19: BBoooxIV | G19: skill | H19: 4 | I19: 4 | J19: 5 | K19: 10 | N19: 11 | O19: 7 | P19: 8 | R19: 6 | S19: 2 | T19: 4 | U19: 3 | X19: 1 | AB19: 1 | AD19: 1
A20: 17 | B20: 0 | C20: Blade Brandier | D20: Master Blade Brandier | F20: BBMaster | G20: master | H20: 5 | I20: 5 | J20: 1 | K20: 65 | N20: 22 | O20: 11 | P20: 10 | R20: 6 | S20: 4 | T20: 5 | U20: 4 | W20: 1 | X20: 1 | Y20: 1 | AB20: 1 | AD20: 2
A21: 18 | B21: 1 | C21: Twin Blade | D21: Novice Twin Blade | F21: TBNovice | G21: novice | H21: 0 | I21: 0 | J21: 5 | K21: 25 | M21: Twin_Blades_License | N21: 12 | O21: 9 | P21: 9 | Q21: 2 | R21: 3 | S21: 1 | T21: 3 | U21: 2 | V21: 1 | W21: 1 | X21: 1 | Y21: 1 | AA21: 1 | AB21: 1 | AE21: 1
A22: 19 | B22: 1 | C22: Twin Blade | D22: Aim I | E22: Aim | F22: TBxoooI | G22: skill | H22: 1 | I22: 1 | J22: 2 | K22: 10 | N22: 6 | O22: 3 | P22: 5 | R22: 2 | T22: 3 | U22: 1 | X22: 1 | Y22: 1 | AA22: 1 | AB22: 1
A23: 20 | B23: 1 | C23: Twin Blade | D23: Aim II | F23: TBxoooII | G23: skill | H23: 1 | I23: 2 | J23: 3 | K23: 10 | N23: 6 | O23: 3 | P23: 5 | R23: 2 | T23: 3 | U23: 1 | X23: 1 | Y23: 1 | AA23: 1 | AB23: 1
A24: 21 | B24: 1 | C24: Twin Blade | D24: Aim III | F24: TBxoooIII | G24: skill | H24: 1 | I24: 3 | J24: 4 | K24: 10 | N24: 12 | O24: 5 | P24: 6 | R24: 3 | T24: 3 | U24: 1 | X24: 2 | Y24: 1 | AA24: 1 | AB24: 1 | AE24: 1
A25: 22 | B25: 1 | C25: Twin Blade | D25: Aim IV | F25: TBxoooIV | G25: skill | H25: 1 | I25: 4 | J25: 5 | K25: 10 | N25: 12 | O25: 5 | P25: 6 | R25: 3 | T25: 5 | U25: 1 | X25: 2 | Y25: 1 | AA25: 1 | AB25: 1 | AE25: 1
A26: 23 | B26: 1 | C26: Twin Blade | D26: Close Combat I | E26: Close Combat | F26: TBoxooI | G26: skill | H26: 2 | I26: 1 | J26: 2 | K26: 10 | N26: 12 | O26: 5 | P26: 3 | R26: 3 | S26: 1 | T26: 2 | U26: 2 | W26: 1 | X26: 1 | Y26: 1 | AB26: 1 | AE26: 1
A27: 24 | B27: 1 | C27: Twin Blade | D27: Close Combat II | F27: TBoxooII | G27: skill | H27: 2 | I27: 2 | J27: 3 | K27: 10 | N27: 12 | O27: 5 | P27: 3 | R27: 3 | S27: 1 | T27: 2 | U27: 2 | W27: 1 | X27: 1 | Y27: 1 | AB27: 1 | AE27: 1
A28: 25 | B28: 1 | C28: Twin Blade | D28: Close Combat III | F28: TBoxooIII | G28: skill | H28: 2 | I28: 3 | J28: 4 | K28: 10 | N28: 18 | O28: 6 | P28: 4 | R28: 4 | S28: 1 | T28: 2 | U28: 3 | W28: 1 | X28: 1 | Y28: 1 | AB28: 1 | AE28: 1
A29: 26 | B29: 1 | C29: Twin Blade | D29: Close Combat IV | F29: TBoxooIV | G29: skill | H29: 2 | I29: 4 | J29: 5 | K29: 10 | N29: 18 | O29: 6 | P29: 4 | R29: 4 | S29: 1 | T29: 4 | U29: 3 | W29: 1 | X29: 1 | Y29: 1 | AB29: 1 | AE29: 1
A30: 27 | B30: 1 | C30: Twin Blade | D30: Stealth I | E30: Stealth | F30: TBooxoI | G30: skill | H30: 3 | I30: 1 | J30: 2 | K30: 10 | N30: 6 | O30: 4 | P30: 4 | R30: 2 | T30: 2 | U30: 3 | W30: 1 | X30: 1 | Y30: 1 | AA30: 1 | AB30: 1 | AE30: 1
A31: 28 | B31: 1 | C31: Twin Blade | D31: Stealth II | F31: TBooxoII | G31: skill | H31: 3 | I31: 2 | J31: 3 | K31: 10 | N31: 6 | O31: 4 | P31: 4 | R31: 2 | T31: 2 | U31: 3 | W31: 1 | X31: 1 | Y31: 1 | AA31: 1 | AB31: 1 | AE31: 1
A32: 29 | B32: 1 | C32: Twin Blade | D32: Stealth III | F32: TBooxoIII | G32: skill | H32: 3 | I32: 3 | J32: 4 | K32: 10 | N32: 12 | O32: 5 | P32: 5 | R32: 3 | T32: 2 | U32: 4 | W32: 1 | X32: 1 | Y32: 1 | AA32: 1 | AB32: 1 | AE32: 1
A33: 30 | B33: 1 | C33: Twin Blade | D33: Stealth IV | F33: TBooxoIV | G33: skill | H33: 3 | I33: 4 | J33: 5 | K33: 10 | N33: 12 | O33: 5 | P33: 5 | R33: 3 | T33: 4 | U33: 4 | W33: 1 | X33: 1 | Y33: 1 | AA33: 1 | AB33: 1 | AE33: 1
A34: 31 | B34: 1 | C34: Twin Blade | D34: Tracking I | E34: Tracking | F34: TBoooxI | G34: skill | H34: 4 | I34: 1 | J34: 2 | K34: 10 | N34: 6 | O34: 3 | P34: 4 | Q34: 1 | R34: 2 | S34: 1 | T34: 2 | U34: 2 | W34: 1 | X34: 1 | Y34: 1 | AA34: 1 | AB34: 1 | AE34: 1
A35: 32 | B35: 1 | C35: Twin Blade | D35: Tracking II | F35: TBoooxII | G35: skill | H35: 4 | I35: 2 | J35: 3 | K35: 10 | N35: 6 | O35: 3 | P35: 4 | Q35: 1 | R35: 2 | S35: 1 | T35: 2 | U35: 2 | W35: 1 | X35: 1 | Y35: 1 | AA35: 1 | AB35: 1 | AE35: 1
A36: 33 | B36: 1 | C36: Twin Blade | D36: Tracking III | F36: TBoooxIII | G36: skill | H36: 4 | I36: 3 | J36: 4 | K36: 10 | N36: 12 | O36: 5 | P36: 5 | Q36: 1 | R36: 3 | S36: 1 | T36: 2 | U36: 2 | W36: 1 | X36: 2 | Y36: 1 | AA36: 1 | AB36: 1 | AE36: 1
A37: 34 | B37: 1 | C37: Twin Blade | D37: Tracking IV | F37: TBoooxIV | G37: skill | H37: 4 | I37: 4 | J37: 5 | K37: 10 | N37: 12 | O37: 5 | P37: 5 | Q37: 1 | R37: 3 | S37: 1 | T37: 2 | U37: 2 | W37: 1 | X37: 2 | Y37: 1 | AA37: 1 | AB37: 1 | AE37: 1
A38: 35 | B38: 1 | C38: Twin Blade | D38: Master Twin Blade | F38: TBMaster | G38: master | H38: 5 | I38: 5 | J38: 1 | K38: 65 | N38: 24 | O38: 8 | P38: 8 | Q38: 3 | R38: 4 | S38: 2 | T38: 4 | U38: 4 | V38: 1 | W38: 2 | X38: 2 | Y38: 2 | AA38: 2 | AB38: 2 | AD38: 1 | AE38: 2
A39: 36 | B39: 2 | C39: Wave User | D39: Novice Wave User | F39: WUNovice | G39: novice | H39: 0 | I39: 0 | J39: 5 | K39: 25 | M39: Focus_License | N39: 14 | O39: 6 | P39: 4 | Q39: 16 | R39: 1 | S39: 1 | T39: 3 | U39: 3 | V39: 6 | W39: 5 | X39: 5 | Y39: 4 | Z39: 1 | AA39: 3 | AB39: 3 | AD39: 3
A40: 37 | B40: 2 | C40: Wave User | D40: Wave Magic I | E40: Wave Magic | F40: WUxoooI | G40: skill | H40: 1 | I40: 1 | J40: 2 | K40: 10 | N40: 5 | O40: 2 | Q40: 9 | T40: 1 | V40: 4 | W40: 1 | X40: 3 | Y40: 1 | Z40: 1 | AA40: 2 | AB40: 1 | AD40: 1
...

Sheet Skills
A1: One row per skill. class_id links to Classes. skill_box_id links to SkillBoxes — this is which box the skill belongs to (players must unlock the box to get the skill). resource: SP | TP | MP | none. target: Single | AOE | Self | Ally. power is a multiplier on base PATK/MATK. Leave effect columns blank if no status effect. Effect_type matches to Skills_Effects. Effect_duration is how many "turns" of combat it lasts. Effect_value is how strong the effect is. Effect_target helps explain which stat or property is modified by the skill. Element helps identify how the skill works on the Elements amplification.
A2: id | B2: name | C2: class_id | D2: class_name (reference) | E2: skill_box_id | F2: skill_box_name (reference) | G2: cost | H2: resource | I2: damage_type | J2: target | K2: power | L2: effect_type | M2: effect_duration | N2: effect_value | O2: effect_target | P2: skill_element | Q2: notes
A3: 0 | B3: Draw Strike | C3: {=INDEX(SkillBoxes!A2:D578,MATCH(E3,SkillBoxes!A2:A578,0),2)} -> 0 | D3: {=INDEX(SkillBoxes!A2:D578,MATCH(E3,SkillBoxes!A2:A578,0),3)} -> Blade Brandier | E3: 0 | F3: {=INDEX(SkillBoxes!A2:D578,MATCH(E3,SkillBoxes!A2:A578,0),4)} -> Novice Blade Brandier | G3: 4 | H3: SP | I3: Physical | J3: Single | K3: 1
A4: 1 | B4: Cross Slash I | C4: {=INDEX(SkillBoxes!A3:D579,MATCH(E4,SkillBoxes!A3:A579,0),2)} -> 0 | D4: {=INDEX(SkillBoxes!A3:D579,MATCH(E4,SkillBoxes!A3:A579,0),3)} -> Blade Brandier | E4: 1 | F4: {=INDEX(SkillBoxes!A3:D579,MATCH(E4,SkillBoxes!A3:A579,0),4)} -> Sword Handling I | G4: 6 | H4: SP | I4: Physical | J4: Single | K4: 1.1
A5: 2 | B5: Cross Slash II | C5: {=INDEX(SkillBoxes!A4:D580,MATCH(E5,SkillBoxes!A4:A580,0),2)} -> 0 | D5: {=INDEX(SkillBoxes!A4:D580,MATCH(E5,SkillBoxes!A4:A580,0),3)} -> Blade Brandier | E5: 2 | F5: {=INDEX(SkillBoxes!A4:D580,MATCH(E5,SkillBoxes!A4:A580,0),4)} -> Sword Handling II | G5: 8 | H5: SP | I5: Physical | J5: Single | K5: 1.2
A6: 3 | B6: Cross Slash III | C6: {=INDEX(SkillBoxes!A5:D581,MATCH(E6,SkillBoxes!A5:A581,0),2)} -> 0 | D6: {=INDEX(SkillBoxes!A5:D581,MATCH(E6,SkillBoxes!A5:A581,0),3)} -> Blade Brandier | E6: 3 | F6: {=INDEX(SkillBoxes!A5:D581,MATCH(E6,SkillBoxes!A5:A581,0),4)} -> Sword Handling III | G6: 10 | H6: SP | I6: Physical | J6: Single | K6: 1.4 | L6: Bleed | M6: 3 | N6: -2 | O6: HP
A7: 4 | B7: Cross Slash IV | C7: {=INDEX(SkillBoxes!A6:D582,MATCH(E7,SkillBoxes!A6:A582,0),2)} -> 0 | D7: {=INDEX(SkillBoxes!A6:D582,MATCH(E7,SkillBoxes!A6:A582,0),3)} -> Blade Brandier | E7: 4 | F7: {=INDEX(SkillBoxes!A6:D582,MATCH(E7,SkillBoxes!A6:A582,0),4)} -> Sword Handling IV | G7: 12 | H7: SP | I7: Physical | J7: Single | K7: 1.6 | L7: Bleed | M7: 5 | N7: -4 | O7: HP
A8: 5 | B8: Rising Cut I | C8: {=INDEX(SkillBoxes!A7:D583,MATCH(E8,SkillBoxes!A7:A583,0),2)} -> 0 | D8: {=INDEX(SkillBoxes!A7:D583,MATCH(E8,SkillBoxes!A7:A583,0),3)} -> Blade Brandier | E8: 5 | F8: {=INDEX(SkillBoxes!A7:D583,MATCH(E8,SkillBoxes!A7:A583,0),4)} -> Sword Techniques I | G8: 6 | H8: SP | I8: Physical | J8: Single | K8: 1.2 | L8: Curse | M8: 2 | N8: 0.05 | O8: PDEF
A9: 6 | B9: Rising Cut II | C9: {=INDEX(SkillBoxes!A8:D584,MATCH(E9,SkillBoxes!A8:A584,0),2)} -> 0 | D9: {=INDEX(SkillBoxes!A8:D584,MATCH(E9,SkillBoxes!A8:A584,0),3)} -> Blade Brandier | E9: 6 | F9: {=INDEX(SkillBoxes!A8:D584,MATCH(E9,SkillBoxes!A8:A584,0),4)} -> Sword Techniques II | G9: 8 | H9: SP | I9: Physical | J9: Single | K9: 1.35 | L9: Curse | M9: 3 | N9: 0.1 | O9: PDEF
A10: 7 | B10: Pommel Strike | C10: {=INDEX(SkillBoxes!A9:D585,MATCH(E10,SkillBoxes!A9:A585,0),2)} -> 0 | D10: {=INDEX(SkillBoxes!A9:D585,MATCH(E10,SkillBoxes!A9:A585,0),3)} -> Blade Brandier | E10: 7 | F10: {=INDEX(SkillBoxes!A9:D585,MATCH(E10,SkillBoxes!A9:A585,0),4)} -> Sword Techniques III | G10: 10 | H10: SP | I10: Physical | J10: Single | K10: 0.8 | L10: Stun | M10: 2
A11: 8 | B11: Blade Storm | C11: {=INDEX(SkillBoxes!A10:D586,MATCH(E11,SkillBoxes!A10:A586,0),2)} -> 0 | D11: {=INDEX(SkillBoxes!A10:D586,MATCH(E11,SkillBoxes!A10:A586,0),3)} -> Blade Brandier | E11: 8 | F11: {=INDEX(SkillBoxes!A10:D586,MATCH(E11,SkillBoxes!A10:A586,0),4)} -> Sword Techniques IV | G11: 8 | H11: TP | I11: Physical | J11: AOE | K11: 0.7
A12: 9 | B12: Crescent Draw I | C12: {=INDEX(SkillBoxes!A11:D587,MATCH(E12,SkillBoxes!A11:A587,0),2)} -> 0 | D12: {=INDEX(SkillBoxes!A11:D587,MATCH(E12,SkillBoxes!A11:A587,0),3)} -> Blade Brandier | E12: 9 | F12: {=INDEX(SkillBoxes!A11:D587,MATCH(E12,SkillBoxes!A11:A587,0),4)} -> Sword Arts I | G12: 6 | H12: SP | I12: Physical | J12: Single | K12: 1.3 | P12: Light
A13: 10 | B13: Crescent Draw II | C13: {=INDEX(SkillBoxes!A12:D588,MATCH(E13,SkillBoxes!A12:A588,0),2)} -> 0 | D13: {=INDEX(SkillBoxes!A12:D588,MATCH(E13,SkillBoxes!A12:A588,0),3)} -> Blade Brandier | E13: 10 | F13: {=INDEX(SkillBoxes!A12:D588,MATCH(E13,SkillBoxes!A12:A588,0),4)} -> Sword Arts II | G13: 8 | H13: SP | I13: Physical | J13: Single | K13: 1.5 | P13: Light
A14: 11 | B14: Mirror Slash | C14: {=INDEX(SkillBoxes!A13:D589,MATCH(E14,SkillBoxes!A13:A589,0),2)} -> 0 | D14: {=INDEX(SkillBoxes!A13:D589,MATCH(E14,SkillBoxes!A13:A589,0),3)} -> Blade Brandier | E14: 11 | F14: {=INDEX(SkillBoxes!A13:D589,MATCH(E14,SkillBoxes!A13:A589,0),4)} -> Sword Arts III | G14: 15 | H14: MP | I14: Physical | J14: Self | K14: 0 | L14: Mirror | M14: 1
A15: 12 | B15: Radiant Edge | C15: {=INDEX(SkillBoxes!A14:D590,MATCH(E15,SkillBoxes!A14:A590,0),2)} -> 0 | D15: {=INDEX(SkillBoxes!A14:D590,MATCH(E15,SkillBoxes!A14:A590,0),3)} -> Blade Brandier | E15: 12 | F15: {=INDEX(SkillBoxes!A14:D590,MATCH(E15,SkillBoxes!A14:A590,0),4)} -> Sword Arts IV | G15: 20 | H15: MP | I15: Magical | J15: Single | K15: 1.5 | P15: Light
A16: 13 | B16: Slashing Blade I | C16: {=INDEX(SkillBoxes!A15:D591,MATCH(E16,SkillBoxes!A15:A591,0),2)} -> 0 | D16: {=INDEX(SkillBoxes!A15:D591,MATCH(E16,SkillBoxes!A15:A591,0),3)} -> Blade Brandier | E16: 13 | F16: {=INDEX(SkillBoxes!A15:D591,MATCH(E16,SkillBoxes!A15:A591,0),4)} -> Slashing Blade I | G16: 6 | H16: SP | I16: Physical | J16: Single | K16: 1.1
A17: 14 | B17: Slashing Blade II | C17: {=INDEX(SkillBoxes!A16:D592,MATCH(E17,SkillBoxes!A16:A592,0),2)} -> 0 | D17: {=INDEX(SkillBoxes!A16:D592,MATCH(E17,SkillBoxes!A16:A592,0),3)} -> Blade Brandier | E17: 14 | F17: {=INDEX(SkillBoxes!A16:D592,MATCH(E17,SkillBoxes!A16:A592,0),4)} -> Slashing Blade II | G17: 8 | H17: SP | I17: Physical | J17: Single | K17: 1.2
A18: 15 | B18: Slashing Blade III | C18: {=INDEX(SkillBoxes!A17:D593,MATCH(E18,SkillBoxes!A17:A593,0),2)} -> 0 | D18: {=INDEX(SkillBoxes!A17:D593,MATCH(E18,SkillBoxes!A17:A593,0),3)} -> Blade Brandier | E18: 15 | F18: {=INDEX(SkillBoxes!A17:D593,MATCH(E18,SkillBoxes!A17:A593,0),4)} -> Slashing Blade III | G18: 10 | H18: SP | I18: Physical | J18: Single | K18: 1.4
A19: 16 | B19: Slashing Blade IV | C19: {=INDEX(SkillBoxes!A18:D594,MATCH(E19,SkillBoxes!A18:A594,0),2)} -> 0 | D19: {=INDEX(SkillBoxes!A18:D594,MATCH(E19,SkillBoxes!A18:A594,0),3)} -> Blade Brandier | E19: 16 | F19: {=INDEX(SkillBoxes!A18:D594,MATCH(E19,SkillBoxes!A18:A594,0),4)} -> Slashing Blade IV | G19: 12 | H19: SP | I19: Physical | J19: Single | K19: 1.6
A20: 17 | B20: Blade Storm II | C20: {=INDEX(SkillBoxes!A19:D595,MATCH(E20,SkillBoxes!A19:A595,0),2)} -> 0 | D20: {=INDEX(SkillBoxes!A19:D595,MATCH(E20,SkillBoxes!A19:A595,0),3)} -> Blade Brandier | E20: 17 | F20: {=INDEX(SkillBoxes!A19:D595,MATCH(E20,SkillBoxes!A19:A595,0),4)} -> Master Blade Brandier | G20: 12 | H20: TP | I20: Physical | J20: AOE | K20: 0.9
A21: 18 | B21: Twin Fang | C21: {=INDEX(SkillBoxes!A20:D596,MATCH(E21,SkillBoxes!A20:A596,0),2)} -> 1 | D21: {=INDEX(SkillBoxes!A20:D596,MATCH(E21,SkillBoxes!A20:A596,0),3)} -> Twin Blade | E21: 18 | F21: {=INDEX(SkillBoxes!A20:D596,MATCH(E21,SkillBoxes!A20:A596,0),4)} -> Novice Twin Blade | G21: 4 | H21: SP | I21: Physical | J21: Single | K21: 1
A22: 19 | B22: Pinpoint I | C22: {=INDEX(SkillBoxes!A21:D597,MATCH(E22,SkillBoxes!A21:A597,0),2)} -> 1 | D22: {=INDEX(SkillBoxes!A21:D597,MATCH(E22,SkillBoxes!A21:A597,0),3)} -> Twin Blade | E22: 19 | F22: {=INDEX(SkillBoxes!A21:D597,MATCH(E22,SkillBoxes!A21:A597,0),4)} -> Aim I | G22: 6 | H22: SP | I22: Physical | J22: Single | K22: 1.1
A23: 20 | B23: Pinpoint II | C23: {=INDEX(SkillBoxes!A22:D598,MATCH(E23,SkillBoxes!A22:A598,0),2)} -> 1 | D23: {=INDEX(SkillBoxes!A22:D598,MATCH(E23,SkillBoxes!A22:A598,0),3)} -> Twin Blade | E23: 20 | F23: {=INDEX(SkillBoxes!A22:D598,MATCH(E23,SkillBoxes!A22:A598,0),4)} -> Aim II | G23: 8 | H23: SP | I23: Physical | J23: Single | K23: 1.2
A24: 21 | B24: Blade Sight | C24: {=INDEX(SkillBoxes!A23:D599,MATCH(E24,SkillBoxes!A23:A599,0),2)} -> 1 | D24: {=INDEX(SkillBoxes!A23:D599,MATCH(E24,SkillBoxes!A23:A599,0),3)} -> Twin Blade | E24: 21 | F24: {=INDEX(SkillBoxes!A23:D599,MATCH(E24,SkillBoxes!A23:A599,0),4)} -> Aim III | G24: 10 | H24: TP | I24: Physical | J24: Single | K24: 1.4 | L24: Curse | M24: 2 | N24: 0.05 | O24: PHIT
A25: 22 | B25: Target Lock | C25: {=INDEX(SkillBoxes!A24:D600,MATCH(E25,SkillBoxes!A24:A600,0),2)} -> 1 | D25: {=INDEX(SkillBoxes!A24:D600,MATCH(E25,SkillBoxes!A24:A600,0),3)} -> Twin Blade | E25: 22 | F25: {=INDEX(SkillBoxes!A24:D600,MATCH(E25,SkillBoxes!A24:A600,0),4)} -> Aim IV | G25: 12 | H25: TP | I25: Physical | J25: Single | K25: 1.6 | L25: Curse | M25: 3 | N25: 0.1 | O25: PEVA
A26: 23 | B26: Dagger Rush I | C26: {=INDEX(SkillBoxes!A25:D601,MATCH(E26,SkillBoxes!A25:A601,0),2)} -> 1 | D26: {=INDEX(SkillBoxes!A25:D601,MATCH(E26,SkillBoxes!A25:A601,0),3)} -> Twin Blade | E26: 23 | F26: {=INDEX(SkillBoxes!A25:D601,MATCH(E26,SkillBoxes!A25:A601,0),4)} -> Close Combat I | G26: 6 | H26: SP | I26: Physical | J26: Single | K26: 1.1
A27: 24 | B27: Dagger Rush II | C27: {=INDEX(SkillBoxes!A26:D602,MATCH(E27,SkillBoxes!A26:A602,0),2)} -> 1 | D27: {=INDEX(SkillBoxes!A26:D602,MATCH(E27,SkillBoxes!A26:A602,0),3)} -> Twin Blade | E27: 24 | F27: {=INDEX(SkillBoxes!A26:D602,MATCH(E27,SkillBoxes!A26:A602,0),4)} -> Close Combat II | G27: 8 | H27: SP | I27: Physical | J27: Single | K27: 1.25
A28: 25 | B28: Spinning Blades | C28: {=INDEX(SkillBoxes!A27:D603,MATCH(E28,SkillBoxes!A27:A603,0),2)} -> 1 | D28: {=INDEX(SkillBoxes!A27:D603,MATCH(E28,SkillBoxes!A27:A603,0),3)} -> Twin Blade | E28: 25 | F28: {=INDEX(SkillBoxes!A27:D603,MATCH(E28,SkillBoxes!A27:A603,0),4)} -> Close Combat III | G28: 10 | H28: SP | I28: Physical | J28: AOE | K28: 0.9
A29: 26 | B29: Dual Tempest | C29: {=INDEX(SkillBoxes!A28:D604,MATCH(E29,SkillBoxes!A28:A604,0),2)} -> 1 | D29: {=INDEX(SkillBoxes!A28:D604,MATCH(E29,SkillBoxes!A28:A604,0),3)} -> Twin Blade | E29: 26 | F29: {=INDEX(SkillBoxes!A28:D604,MATCH(E29,SkillBoxes!A28:A604,0),4)} -> Close Combat IV | G29: 12 | H29: SP | I29: Physical | J29: Single | K29: 1.5 | L29: Bleed | M29: 2 | N29: -1 | O29: HP
A30: 27 | B30: Shadow Step I | C30: {=INDEX(SkillBoxes!A29:D605,MATCH(E30,SkillBoxes!A29:A605,0),2)} -> 1 | D30: {=INDEX(SkillBoxes!A29:D605,MATCH(E30,SkillBoxes!A29:A605,0),3)} -> Twin Blade | E30: 27 | F30: {=INDEX(SkillBoxes!A29:D605,MATCH(E30,SkillBoxes!A29:A605,0),4)} -> Stealth I | G30: 6 | H30: SP | I30: Physical | J30: Single | K30: 1 | L30: Stun | M30: 1
A31: 28 | B31: Shadow Step II | C31: {=INDEX(SkillBoxes!A30:D606,MATCH(E31,SkillBoxes!A30:A606,0),2)} -> 1 | D31: {=INDEX(SkillBoxes!A30:D606,MATCH(E31,SkillBoxes!A30:A606,0),3)} -> Twin Blade | E31: 28 | F31: {=INDEX(SkillBoxes!A30:D606,MATCH(E31,SkillBoxes!A30:A606,0),4)} -> Stealth II | G31: 8 | H31: SP | I31: Physical | J31: Single | K31: 1.15 | L31: Stun | M31: 2
A32: 29 | B32: Vanishing Slash | C32: {=INDEX(SkillBoxes!A31:D607,MATCH(E32,SkillBoxes!A31:A607,0),2)} -> 1 | D32: {=INDEX(SkillBoxes!A31:D607,MATCH(E32,SkillBoxes!A31:A607,0),3)} -> Twin Blade | E32: 29 | F32: {=INDEX(SkillBoxes!A31:D607,MATCH(E32,SkillBoxes!A31:A607,0),4)} -> Stealth III | G32: 10 | H32: TP | I32: Physical | J32: Single | K32: 1.3 | L32: Curse | M32: 2 | N32: 0.05 | O32: PHIT
A33: 30 | B33: Assassin's Veil | C33: {=INDEX(SkillBoxes!A32:D608,MATCH(E33,SkillBoxes!A32:A608,0),2)} -> 1 | D33: {=INDEX(SkillBoxes!A32:D608,MATCH(E33,SkillBoxes!A32:A608,0),3)} -> Twin Blade | E33: 30 | F33: {=INDEX(SkillBoxes!A32:D608,MATCH(E33,SkillBoxes!A32:A608,0),4)} -> Stealth IV | G33: 12 | H33: TP | I33: Physical | J33: Self | K33: 0 | L33: Buff | M33: 2 | N33: 0.15 | O33: PEVA
A34: 31 | B34: Mark Target I | C34: {=INDEX(SkillBoxes!A33:D609,MATCH(E34,SkillBoxes!A33:A609,0),2)} -> 1 | D34: {=INDEX(SkillBoxes!A33:D609,MATCH(E34,SkillBoxes!A33:A609,0),3)} -> Twin Blade | E34: 31 | F34: {=INDEX(SkillBoxes!A33:D609,MATCH(E34,SkillBoxes!A33:A609,0),4)} -> Tracking I | G34: 6 | H34: SP | I34: Physical | J34: Single | K34: 1.1
A35: 32 | B35: Mark Target II | C35: {=INDEX(SkillBoxes!A34:D610,MATCH(E35,SkillBoxes!A34:A610,0),2)} -> 1 | D35: {=INDEX(SkillBoxes!A34:D610,MATCH(E35,SkillBoxes!A34:A610,0),3)} -> Twin Blade | E35: 32 | F35: {=INDEX(SkillBoxes!A34:D610,MATCH(E35,SkillBoxes!A34:A610,0),4)} -> Tracking II | G35: 8 | H35: SP | I35: Physical | J35: Single | K35: 1.2 | L35: Bleed | M35: 2 | N35: -1 | O35: HP
A36: 33 | B36: Pursuit Strike | C36: {=INDEX(SkillBoxes!A35:D611,MATCH(E36,SkillBoxes!A35:A611,0),2)} -> 1 | D36: {=INDEX(SkillBoxes!A35:D611,MATCH(E36,SkillBoxes!A35:A611,0),3)} -> Twin Blade | E36: 33 | F36: {=INDEX(SkillBoxes!A35:D611,MATCH(E36,SkillBoxes!A35:A611,0),4)} -> Tracking III | G36: 10 | H36: SP | I36: Physical | J36: Single | K36: 1.4 | L36: Bleed | M36: 3 | N36: -2 | O36: HP
A37: 34 | B37: Prey Sense | C37: {=INDEX(SkillBoxes!A36:D612,MATCH(E37,SkillBoxes!A36:A612,0),2)} -> 1 | D37: {=INDEX(SkillBoxes!A36:D612,MATCH(E37,SkillBoxes!A36:A612,0),3)} -> Twin Blade | E37: 34 | F37: {=INDEX(SkillBoxes!A36:D612,MATCH(E37,SkillBoxes!A36:A612,0),4)} -> Tracking IV | G37: 12 | H37: TP | I37: Physical | J37: Single | K37: 1.5 | L37: Bleed | M37: 4 | N37: -3 | O37: HP | P37: Dark
A38: 35 | B38: Twin Phantom | C38: {=INDEX(SkillBoxes!A37:D613,MATCH(E38,SkillBoxes!A37:A613,0),2)} -> 1 | D38: {=INDEX(SkillBoxes!A37:D613,MATCH(E38,SkillBoxes!A37:A613,0),3)} -> Twin Blade | E38: 35 | F38: {=INDEX(SkillBoxes!A37:D613,MATCH(E38,SkillBoxes!A37:A613,0),4)} -> Master Twin Blade | G38: 14 | H38: TP | I38: Physical | J38: AOE | K38: 1 | L38: Bleed | M38: 3 | N38: -3 | O38: HP
A39: 36 | B39: Wave Pulse | C39: {=INDEX(SkillBoxes!A38:D614,MATCH(E39,SkillBoxes!A38:A614,0),2)} -> 2 | D39: {=INDEX(SkillBoxes!A38:D614,MATCH(E39,SkillBoxes!A38:A614,0),3)} -> Wave User | E39: 36 | F39: {=INDEX(SkillBoxes!A38:D614,MATCH(E39,SkillBoxes!A38:A614,0),4)} -> Novice Wave User | G39: 4 | H39: MP | I39: Magical | J39: Single | K39: 1
A40: 37 | B40: Drain I | C40: {=INDEX(SkillBoxes!A39:D615,MATCH(E40,SkillBoxes!A39:A615,0),2)} -> 2 | D40: {=INDEX(SkillBoxes!A39:D615,MATCH(E40,SkillBoxes!A39:A615,0),3)} -> Wave User | E40: 37 | F40: {=INDEX(SkillBoxes!A39:D615,MATCH(E40,SkillBoxes!A39:A615,0),4)} -> Wave Magic I | G40: 6 | H40: MP | I40: Magical | J40: Single | K40: 1.1
...

Sheet Skills_Effects
A1: One row per effect. Description gives rough explanation for how each effect works. Notes adds extra explanation if necessary.
A2: id | B2: effect | C2: description | D2: notes
A3: 0 | B3: heal | C3: Target recovers HP.
A4: 1 | B4: barrier | C4: Target reflects incoming matching-damage-type for skill duration.
A5: 2 | B5: curse | C5: Target's stats decrease for curse duration.
A6: 3 | B6: bleed | C6: Target becomes wounded. Loses health per turn.
A7: 4 | B7: buff | C7: Target's stats increase for buff duration. | D7: Can target specific stat, depending on skill, including elemental statuses. (HP, SP, TP, MP, PATK, PDEF, PHIT, PEVA, MATK, MDEF, MHIT, MEVA, FIR, WTR, AIR, ERT ,LGT, DRK)
A8: 5 | B8: stun | C8: Target becomes slowed. Target's initiative decreases during effect. Can recover by being hastened.
A9: 6 | B9: burn | C9: Target becomes burned. Loses health per turn.
A10: 7 | B10: freeze | C10: Target becomes frozen. Cannot act. Can negate freeze by attacking with fire-type attacks.
A11: 8 | B11: paralyze | C11: Target becomes paralyzed. Cannot act.
A12: 9 | B12: sleep | C12: Target becomes asleep. Cannot act. Can be woken on hit.
A13: 10 | B13: poison | C13: Target becomes poisoned. Loses health per turn.
A14: 11 | B14: petrify | C14: Target becomes stone. Cannot act. Can become freed on hit.
A15: 12 | B15: silence | C15: Cannot use magic skills.
A16: 13 | B16: frail | C16: Cannot use physical skills.
A17: 14 | B17: haste | C17: Target becomes hastened. Target's initiative increases during effect. Can counter by being slowed.
A18: 15 | B18: root | C18: Target becomes imobilized. Target's initiative decreases severely.
A19: 16 | B19: charm | C19: Target is charmed. Target will attack allies for duration.
... A26: 23 | B26: relaxed | C26: Target has increased Stamina recovery for skill duration.

Sheet ClassPromotionRules
A1: Defines which class unlocks which. boxes_required and specific box conditions are TBD — yellow rows need your decision. prereq_class is already filled from your data. NOTE: which specific branch boxes trigger promotion has not yet been decided.
A2: id | B2: unlocks_class_id | C2: unlocks_class_name | D2: prereq_class_name | E2: sp_pool_required | F2: boxes_required | G2: total_boxes_in_prereq | H2: notes | I2: _TODO
A3: 0 | B3: 4 | C3: Guard Knight | D3: Blade Brandier | E3: 750 | F3: [0,1,2,3,4] | G3: 5
A4: 1 | B4: 5 | C4: Branded Barbarian | D4: Blade Brandier | E4: 750 | F4: [0,1,2,3,4,5,6,7,8,9,10,11,12,13,14,15,16,17] | G4: 18
A5: 2 | B5: 6 | C5: Curse Knight | D5: Blade Brandier | E5: 750 | F5: [0,9,10,11,12] | G5: 5
A6: 3 | B6: 7 | C6: Acro Archer | D6: Twin Blade | E6: 750 | F6: [18,19,20,21,22] | G6: 5
A7: 4 | B7: 8 | C7: Pistol Ranger | D7: Twin Blade | E7: 750 | F7: [18,23,24,25,26] | G7: 5
A8: 5 | B8: 9 | C8: Umbral Assassin | D8: Twin Blade | E8: 750 | F8: [18,27,28,29,30] | G8: 5
A9: 6 | B9: 10 | C9: Arcane Wavemaster | D9: Wave User | E9: 750 | F9: [36,37,38,39,40,49,50,51,52] | G9: 9
A10: 7 | B10: 11 | C10: Tome Summoner | D10: Wave User | E10: 750 | F10: [36,41,42,43,44,45,46,47,48] | G10: 9
A11: 8 | B11: 12 | C11: Aura Priest | D11: Harvest Cleric | E11: 750 | F11: [54,55,56,57,58,59,60,61,62] | G11: 9
A12: 9 | B12: 13 | C12: Martial Monk | D12: Harvest Cleric | E12: 750 | F12: [54,63,64,65,66,67,68,69,70] | G12: 9
A13: 10 | B13: 14 | C13: Runic Paladin | D13: Guard Knight | E13: 1000 | F13: [72,73,74,75,76,77,78,79,80] | G13: 9
A14: 11 | B14: 15 | C14: Long Arm | D14: Guard Knight | E14: 1000 | F14: [72,81,82,83,84,85,86,87,88] | G14: 9
... A30: 27 | B30: 31 | C30: Macbre Dancer | D30: Martial Monk | E30: 1000 | F30: [234,239,240,241,242,243,244,245,246] | G30: 9

Sheet Stats
A1: Reference table for all stat abbreviations used in SkillBoxes.
A2: id | B2: abbreviation | C2: full_name | D2: description | E2: notes
A3: 0 | B3: HP | C3: Health Points | D3: Character health. Reaches 0 = death.
A4: 1 | B4: SP | C4: Skill Points | D4: Resource for physical skills.
A5: 2 | B5: TP | C5: Technique Points | D5: Resource for technique-based skills.
A6: 3 | B6: MP | C6: Magic Points | D6: Resource for magic/wave skills.
A7: 4 | B7: PATK | C7: Physical Attack | D7: Base physical damage.
A8: 5 | B8: PDEF | C8: Physical Defence | D8: Reduces incoming physical damage.
A9: 6 | B9: PHIT | C9: Physical Hit | D9: Accuracy for physical attacks.
A10: 7 | B10: PEVA | C10: Physical Evasion | D10: Chance to dodge physical attacks.
A11: 8 | B11: MATK | C11: Magic Attack | D11: Base magic damage.
A12: 9 | B12: MDEF | C12: Magic Defence | D12: Reduces incoming magic damage.
A13: 10 | B13: MHIT | C13: Magic Hit | D13: Accuracy for magic attacks.
A14: 11 | B14: MEVA | C14: Magic Evasion | D14: Chance to dodge magic attacks.
... A21: 18 | B21: STAM | C21: Stamina | D21: Stamina is used to conduct professions such as crafting, farming, fishing, etc. Can be recovered over time or by consuming stamina-healing items.

Sheet Elements
A1: Elemental counter relationships.
A2: id | B2: element | C2: counter_element | D2: notes
A3: 0 | B3: Fire | C3: Earth
A4: 1 | B4: Water | C4: Air
A5: 2 | B5: Air | C5: Fire
A6: 3 | B6: Earth | C6: Water
A7: 4 | B7: Light | C7: Dark
A8: 5 | B8: Dark | C8: Light

Sheet Weapon_Types
A1: One row per weapon type. range: Short | Medium | Long. weight_class: Light | Medium | Heavy. Weapons can be equipped by all classes. Players require a License to use a weapon at 100% effectiveness. if they do not have a license, the weapon works at 70% scale.
A2: id | B2: type | C2: exp_pool_a | D2: exp_pool_b | E2: range | F2: weight_class | G2: rarity | H2: required_certificate | I2: notes
A3: 0 | B3: Blade | C3: Slashing Weapons | D3: Piercing Weapons | E3: short | F3: Heavy | G3: common | H3: =IFERROR(__xludf.DUMMYFUNCTION("JOIN(""_"",split(B3,"" "",true),""License"")"),"Blade_License") -> Blade_License
A4: 1 | B4: Long Blade | C4: Slashing Weapons | D4: Piercing Weapons | E4: short | F4: Heavy | G4: common | H4: =IFERROR(__xludf.DUMMYFUNCTION("JOIN(""_"",split(B4,"" "",true),""License"")"),"Long_Blade_License") -> Long_Blade_License
A5: 2 | B5: Shield | C5: Bludgeoning Weapons | D5: Support Weapons | E5: short | F5: Heavy | G5: common | H5: =IFERROR(__xludf.DUMMYFUNCTION("JOIN(""_"",split(B5,"" "",true),""License"")"),"Shield_License") -> Shield_License
A6: 3 | B6: Spear | C6: Piercing Weapons | D6: Slashing Weapons | E6: medium | F6: Heavy | G6: common | H6: =IFERROR(__xludf.DUMMYFUNCTION("JOIN(""_"",split(B6,"" "",true),""License"")"),"Spear_License") -> Spear_License
A7: 4 | B7: Heavy Axe | C7: Slashing Weapons | D7: Bludgeoning Weapons | E7: medium | F7: Heavy | G7: common | H7: =IFERROR(__xludf.DUMMYFUNCTION("JOIN(""_"",split(B7,"" "",true),""License"")"),"Heavy_Axe_License") -> Heavy_Axe_License
A8: 5 | B8: Heavy Blade | C8: Slashing Weapons | D8: Bludgeoning Weapons | E8: short | F8: Heavy | G8: common | H8: =IFERROR(__xludf.DUMMYFUNCTION("JOIN(""_"",split(B8,"" "",true),""License"")"),"Heavy_Blade_License") -> Heavy_Blade_License
A9: 6 | B9: Cursed Blade | C9: Piercing Weapons | D9: Relic Weapons | E9: short | F9: Heavy | G9: common | H9: =IFERROR(__xludf.DUMMYFUNCTION("JOIN(""_"",split(B9,"" "",true),""License"")"),"Cursed_Blade_License") -> Cursed_Blade_License
A10: 7 | B10: Spell Blade | C10: Arcane Weapons | D10: Relic Weapons | E10: medium | F10: Heavy | G10: common | H10: =IFERROR(__xludf.DUMMYFUNCTION("JOIN(""_"",split(B10,"" "",true),""License"")"),"Spell_Blade_License") -> Spell_Blade_License
A11: 8 | B11: Jian Blade | C11: Cursing Weapons | D11: Relic Weapons | E11: long | F11: Heavy | G11: common | H11: =IFERROR(__xludf.DUMMYFUNCTION("JOIN(""_"",split(B11,"" "",true),""License"")"),"Jian_Blade_License") -> Jian_Blade_License
A12: 9 | B12: Twin Blades | C12: Slashing Weapons | D12: Cursing Weapons | E12: short | F12: Medium | G12: common | H12: =IFERROR(__xludf.DUMMYFUNCTION("JOIN(""_"",split(B12,"" "",true),""License"")"),"Twin_Blades_License") -> Twin_Blades_License
A13: 10 | B13: Bow | C13: Piercing Weapons | D13: Support Weapons | E13: long | F13: Medium | G13: common | H13: =IFERROR(__xludf.DUMMYFUNCTION("JOIN(""_"",split(B13,"" "",true),""License"")"),"Bow_License") -> Bow_License
A14: 11 | B14: Heavy Bow | C14: Piercing Weapons | D14: Bludgeoning Weapons | E14: long | F14: Medium | G14: common | H14: =IFERROR(__xludf.DUMMYFUNCTION("JOIN(""_"",split(B14,"" "",true),""License"")"),"Heavy_Bow_License") -> Heavy_Bow_License
A15: 12 | B15: Rifle | C15: Piercing Weapons | D15: Support Weapons | E15: long | F15: Medium | G15: common | H15: =IFERROR(__xludf.DUMMYFUNCTION("JOIN(""_"",split(B15,"" "",true),""License"")"),"Rifle_License") -> Rifle_License
A16: 13 | B16: Dual Guns | C16: Piercing Weapons | D16: Cursing Weapons | E16: short | F16: Medium | G16: common | H16: =IFERROR(__xludf.DUMMYFUNCTION("JOIN(""_"",split(B16,"" "",true),""License"")"),"Dual_Guns_License") -> Dual_Guns_License
A17: 14 | B17: Bayonet | C17: Piercing Weapons | D17: Slashing Weapons | E17: medium | F17: Medium | G17: common | H17: =IFERROR(__xludf.DUMMYFUNCTION("JOIN(""_"",split(B17,"" "",true),""License"")"),"Bayonet_License") -> Bayonet_License
A18: 15 | B18: Claws | C18: Slashing Weapons | D18: Relic Weapons | E18: short | F18: Medium | G18: common | H18: =IFERROR(__xludf.DUMMYFUNCTION("JOIN(""_"",split(B18,"" "",true),""License"")"),"Claws_License") -> Claws_License
A19: 16 | B19: Gauntlets | C19: Bludgeoning Weapons | D19: Relic Weapons | E19: short | F19: Medium | G19: common | H19: =IFERROR(__xludf.DUMMYFUNCTION("JOIN(""_"",split(B19,"" "",true),""License"")"),"Gauntlets_License") -> Gauntlets_License
A20: 17 | B20: Scythe | C20: Cursing Weapons | D20: Slashing Weapons | E20: medium | F20: Medium | G20: common | H20: =IFERROR(__xludf.DUMMYFUNCTION("JOIN(""_"",split(B20,"" "",true),""License"")"),"Scythe_License") -> Scythe_License
A21: 18 | B21: Focus | C21: Arcane Weapons | D21: Support Weapons | E21: medium | F21: Light | G21: common | H21: =IFERROR(__xludf.DUMMYFUNCTION("JOIN(""_"",split(B21,"" "",true),""License"")"),"Focus_License") -> Focus_License
A22: 19 | B22: Staff | C22: Support Weapons | D22: Arcane Weapons | E22: medium | F22: Light | G22: common | H22: =IFERROR(__xludf.DUMMYFUNCTION("JOIN(""_"",split(B22,"" "",true),""License"")"),"Staff_License") -> Staff_License
A23: 20 | B23: Heavy Staff | C23: Bludgeoning Weapons | D23: Support Weapons | E23: medium | F23: Light | G23: common | H23: =IFERROR(__xludf.DUMMYFUNCTION("JOIN(""_"",split(B23,"" "",true),""License"")"),"Heavy_Staff_License") -> Heavy_Staff_License
A24: 21 | B24: Crystal Staff | C24: Support Weapons | D24: Arcane Weapons | E24: long | F24: Light | G24: common | H24: =IFERROR(__xludf.DUMMYFUNCTION("JOIN(""_"",split(B24,"" "",true),""License"")"),"Crystal_Staff_License") -> Crystal_Staff_License
A25: 22 | B25: Runes | C25: Arcane Weapons | D25: Relic Weapons | E25: medium | F25: Light | G25: common | H25: =IFERROR(__xludf.DUMMYFUNCTION("JOIN(""_"",split(B25,"" "",true),""License"")"),"Runes_License") -> Runes_License
A26: 23 | B26: War Fans | C26: Bludgeoning Weapons | D26: Relic Weapons | E26: long | F26: Light | G26: common | H26: =IFERROR(__xludf.DUMMYFUNCTION("JOIN(""_"",split(B26,"" "",true),""License"")"),"War_Fans_License") -> War_Fans_License
A27: 24 | B27: Necronomicon | C27: Cursing Weapons | D27: Arcane Weapons | E27: long | F27: Light | G27: common | H27: =IFERROR(__xludf.DUMMYFUNCTION("JOIN(""_"",split(B27,"" "",true),""License"")"),"Necronomicon_License") -> Necronomicon_License
A28: 25 | B28: Wand | C28: Arcane Weapons | D28: Relic Weapons | E28: medium | F28: Light | G28: common | H28: =IFERROR(__xludf.DUMMYFUNCTION("JOIN(""_"",split(B28,"" "",true),""License"")"),"Wand_License") -> Wand_License
A29: 26 | B29: Tome | C29: Arcane Weapons | D29: Cursing Weapons | E29: medium | F29: Light | G29: common | H29: =IFERROR(__xludf.DUMMYFUNCTION("JOIN(""_"",split(B29,"" "",true),""License"")"),"Tome_License") -> Tome_License
A30: 27 | B30: Grimoire | C30: Arcane Weapons | D30: Cursing Weapons | E30: long | F30: Light | G30: common | H30: =IFERROR(__xludf.DUMMYFUNCTION("JOIN(""_"",split(B30,"" "",true),""License"")"),"Grimoire_License") -> Grimoire_License
A31: 28 | B31: Holy Relic | C31: Relic Weapons | D31: Support Weapons | E31: long | F31: Light | G31: common | H31: =IFERROR(__xludf.DUMMYFUNCTION("JOIN(""_"",split(B31,"" "",true),""License"")"),"Holy_Relic_License") -> Holy_Relic_License
A32: 29 | B32: Bo Staff | C32: Bludgeoning Weapons | D32: Cursing Weapons | E32: medium | F32: Light | G32: common | H32: =IFERROR(__xludf.DUMMYFUNCTION("JOIN(""_"",split(B32,"" "",true),""License"")"),"Bo_Staff_License") -> Bo_Staff_License
A33: 30 | B33: Whip | C33: Bludgeoning Weapons | D33: Support Weapons | E33: long | F33: Light | G33: common | H33: =IFERROR(__xludf.DUMMYFUNCTION("JOIN(""_"",split(B33,"" "",true),""License"")"),"Whip_License") -> Whip_License
A34: 31 | B34: Bladed Fans | C34: Slashing Weapons | D34: Cursing Weapons | E34: short | F34: Light | G34: common | H34: =IFERROR(__xludf.DUMMYFUNCTION("JOIN(""_"",split(B34,"" "",true),""License"")"),"Bladed_Fans_License") -> Bladed_Fans_License

Sheet Weapons
A1: One row per weapon. Weapons can be equipped by all classes. Players require a License to use a weapon at 100% effectiveness. if they do not have a license, the weapon works at 70% scale.
A2: id | B2: name | C2: type | D2: rarity | E2: HP | F2: SP | G2: TP | H2: MP | I2: PATK | J2: PDEF | K2: PHIT | L2: PEVA | M2: MATK | N2: MDEF | O2: MHIT | P2: MEVA | Q2: FIR | R2: WTR | S2: AIR | T2: ERT | U2: LGT | V2: DRK | W2: notes | X2: _JSON_KEY
A3: 0 | B3: Rusty Blade | C3: Blade | D3: common | F3: 14 | G3: 7 | I3: 4 | J3: 1 | K3: 3 | L3: 1 | X3: weapons
A4: 1 | B4: Rusty Long Blade | C4: Long Blade | D4: common | F4: 4 | G4: 4 | I4: 1 | J4: 1 | K4: 3 | L4: 1 | O4: 1 | X4: weapons
A5: 2 | B5: Rusty Shield | C5: Shield | D5: common | F5: 4 | G5: 6 | I5: 3 | J5: 1 | K5: 3 | L5: 1 | O5: 1 | P5: 1 | S5: 1 | X5: weapons
A6: 3 | B6: Rusty Spear | C6: Spear | D6: common | E6: 7 | F6: 6 | G6: 7 | I6: 3 | J6: 3 | K6: 4 | L6: 3 | N6: 1 | O6: 1 | P6: 1 | S6: 1 | U6: 1 | X6: weapons
A7: 4 | B7: Rusty Heavy Axe | C7: Heavy Axe | D7: common | E7: 7 | F7: 7 | G7: 9 | I7: 4 | J7: 3 | K7: 6 | L7: 3 | N7: 1 | O7: 3 | P7: 3 | S7: 1 | U7: 1 | X7: weapons
A8: 5 | B8: Rusty Heavy Blade | C8: Heavy Blade | D8: common | F8: 6 | G8: 6 | I8: 3 | J8: 1 | K8: 1 | L8: 1 | N8: 1 | X8: weapons
A9: 6 | B9: Rusty Cursed Blade | C9: Cursed Blade | D9: common | F9: 7 | G9: 7 | I9: 4 | J9: 1 | K9: 1 | L9: 1 | N9: 1 | P9: 1 | X9: weapons
A10: 7 | B10: Rusty Spell Blade | C10: Spell Blade | D10: common | E10: 7 | F10: 9 | G10: 9 | I10: 4 | J10: 3 | K10: 2 | L10: 2 | N10: 1 | P10: 1 | X10: weapons
A11: 8 | B11: Rusty Jian Blade | C11: Jian Blade | D11: common | E11: 7 | F11: 10 | G11: 10 | I11: 6 | J11: 3 | K11: 2 | L11: 2 | N11: 1 | P11: 1 | X11: weapons
A12: 9 | B12: Rusty Twin Blades | C12: Twin Blades | D12: common | F12: 6 | G12: 4 | I12: 4 | J12: 2 | K12: 2 | L12: 2 | N12: 1 | O12: 1 | X12: weapons
A13: 10 | B13: Rusty Bow | C13: Bow | D13: common | F13: 7 | G13: 5 | I13: 4 | J13: 2 | K13: 2 | L13: 2 | N13: 1 | O13: 1 | X13: weapons
A14: 11 | B14: Rusty Heavy Bow | C14: Heavy Bow | D14: common | E14: 7 | F14: 9 | G14: 6 | I14: 6 | J14: 2 | K14: 3 | L14: 2 | N14: 1 | O14: 1 | X14: weapons
A15: 12 | B15: Rusty Rifle | C15: Rifle | D15: common | E15: 7 | F15: 10 | G15: 7 | I15: 6 | J15: 2 | K15: 3 | L15: 2 | N15: 1 | O15: 1 | X15: weapons
A16: 13 | B16: Rusty Dual Guns | C16: Dual Guns | D16: common | E16: 7 | F16: 6 | G16: 5 | I16: 4 | J16: 2 | K16: 3 | L16: 3 | S16: 1 | X16: weapons
A17: 14 | B17: Rusty Bayonet | C17: Bayonet | D17: common | E17: 7 | F17: 6 | G17: 6 | I17: 4 | J17: 2 | K17: 3 | L17: 3 | S17: 1 | X17: weapons
A18: 15 | B18: Rusty Claws | C18: Claws | D18: common | E18: 11 | F18: 7 | G18: 7 | I18: 6 | J18: 2 | K18: 4 | L18: 3 | O18: 1 | S18: 1 | U18: 1 | X18: weapons
A19: 16 | B19: Rusty Gauntlets | C19: Gauntlets | D19: common | E19: 11 | F19: 7 | G19: 8 | I19: 6 | J19: 2 | K19: 4 | L19: 3 | O19: 1 | S19: 1 | U19: 1 | X19: weapons
A20: 17 | B20: Rusty Scythe | C20: Scythe | D20: common | E20: 22 | F20: 11 | G20: 10 | I20: 6 | J20: 4 | K20: 5 | L20: 4 | N20: 1 | O20: 1 | P20: 1 | S20: 1 | U20: 2 | X20: weapons
A21: 18 | B21: Rusty Focus | C21: Focus | D21: common | E21: 12 | F21: 9 | G21: 9 | H21: 2 | I21: 3 | J21: 1 | K21: 3 | L21: 2 | M21: 1 | N21: 1 | O21: 1 | P21: 1 | R21: 1 | S21: 1 | V21: 1 | X21: weapons
A22: 19 | B22: Rusty Staff | C22: Staff | D22: common | E22: 6 | F22: 3 | G22: 5 | I22: 2 | K22: 3 | L22: 1 | O22: 1 | P22: 1 | R22: 1 | S22: 1 | X22: weapons
A23: 20 | B23: Rusty Heavy Staff | C23: Heavy Staff | D23: common | E23: 6 | F23: 3 | G23: 5 | I23: 2 | K23: 3 | L23: 1 | O23: 1 | P23: 1 | R23: 1 | S23: 1 | X23: weapons
A24: 21 | B24: Rusty Crystal Staff | C24: Crystal Staff | D24: common | E24: 12 | F24: 5 | G24: 6 | I24: 3 | K24: 3 | L24: 1 | O24: 2 | P24: 1 | R24: 1 | S24: 1 | V24: 1 | X24: weapons
A25: 22 | B25: Rusty Runes | C25: Runes | D25: common | E25: 12 | F25: 5 | G25: 6 | I25: 3 | K25: 5 | L25: 1 | O25: 2 | P25: 1 | R25: 1 | S25: 1 | V25: 1 | X25: weapons
A26: 23 | B26: Rusty War Fans | C26: War Fans | D26: common | E26: 12 | F26: 5 | G26: 3 | I26: 3 | J26: 1 | K26: 2 | L26: 2 | N26: 1 | O26: 1 | P26: 1 | S26: 1 | V26: 1 | X26: weapons
A27: 24 | B27: Rusty Necronomicon | C27: Necronomicon | D27: common | E27: 12 | F27: 5 | G27: 3 | I27: 3 | J27: 1 | K27: 2 | L27: 2 | N27: 1 | O27: 1 | P27: 1 | S27: 1 | V27: 1 | X27: weapons
A28: 25 | B28: Rusty Wand | C28: Wand | D28: common | E28: 18 | F28: 6 | G28: 4 | I28: 4 | J28: 1 | K28: 2 | L28: 3 | N28: 1 | O28: 1 | P28: 1 | S28: 1 | V28: 1 | X28: weapons
A29: 26 | B29: Rusty Tome | C29: Tome | D29: common | E29: 18 | F29: 6 | G29: 4 | I29: 4 | J29: 1 | K29: 4 | L29: 3 | N29: 1 | O29: 1 | P29: 1 | S29: 1 | V29: 1 | X29: weapons
A30: 27 | B30: Rusty Grimoire | C30: Grimoire | D30: common | E30: 6 | F30: 4 | G30: 4 | I30: 2 | K30: 2 | L30: 3 | N30: 1 | O30: 1 | P30: 1 | R30: 1 | S30: 1 | V30: 1 | X30: weapons
A31: 28 | B31: Rusty Holy Relic | C31: Holy Relic | D31: common | E31: 6 | F31: 4 | G31: 4 | I31: 2 | K31: 2 | L31: 3 | N31: 1 | O31: 1 | P31: 1 | R31: 1 | S31: 1 | V31: 1 | X31: weapons
A32: 29 | B32: Rusty Bo Staff | C32: Bo Staff | D32: common | E32: 12 | F32: 5 | G32: 5 | I32: 3 | K32: 2 | L32: 4 | N32: 1 | O32: 1 | P32: 1 | R32: 1 | S32: 1 | V32: 1 | X32: weapons
A33: 30 | B33: Rusty Whip | C33: Whip | D33: common | E33: 12 | F33: 5 | G33: 5 | I33: 3 | K33: 4 | L33: 4 | N33: 1 | O33: 1 | P33: 1 | R33: 1 | S33: 1 | V33: 1 | X33: weapons
A34: 31 | B34: Rusty Bladed Fans | C34: Bladed Fans | D34: common | E34: 6 | F34: 3 | G34: 4 | H34: 1 | I34: 2 | J34: 1 | K34: 2 | L34: 2 | N34: 1 | O34: 1 | P34: 1 | R34: 1 | S34: 1 | V34: 1 | X34: weapons

Sheet Rarity_Index
A1: One row per rarity. Rarities add prefixes to various items, identified by headers.
A2: id | B2: name
A3: 0 | B3: Worthless
A4: 1 | B4: Common
A5: 2 | B5: Uncommon
A6: 3 | B6: Quality
A7: 4 | B7: Rare
A8: 5 | B8: Epic
A9: 6 | B9: Unique
A10: 7 | B10: Arcane
A11: 8 | B11: Legendary
A12: 9 | B12: Mythical
A13: 10 | B13: Demonic
A14: 11 | B14: Blessed
... A16: 13 | B16: Cosmic

Sheet Consumables
A1: One row per consumable.
A2: id | B2: name | C2: Effect | D2: Target
A3: 0 | B3: Recovery Drop | C3: Recovers 150 HP | D3: Self / Ally
A4: 1 | B4: Restorative Sap | C4: Recovers 15 SP/TP/MP | D4: Self / Ally
A5: 2 | B5: Goddess Drop | C5: Revive target to 25% HP/SP/TP/MP. | D5: Self / Ally
A6: 3
A7: 4
A8: 5
A9: 6
A10: 7
A11: 8
A12: 9
A13: 10
A14: 11
A15: 12
A16: 13

Sheet Gear_Types
A1: One row per gear type. Gear has three different weights: light, medium, heavy. Gear can slot into specific player Gear Slots, as designated by gear_slot. Most equipment is player-made, defined in the crafting rules. The
A2: id | B2: Type | C2: Gear_Slot | D2: Rarity | I2: notes
A3: 0 | B3: Cap | C3: Head | D3: Common
A4: 1 | B4: Cuirras | C4: Chest | D4: Common
A5: 2 | B5: Boots | C5: Boots | D5: Common
A6: 3 | B6: Ring | C6: Accessory 1 | D6: Common
A7: 4 | B7: Amulet | C7: Accessory 2 | D7: Common
A8: 5
A9: 6
A10: 7
A11: 8
A12: 9
A13: 10

Sheet GearSets
A1: One row per gear set. weight_class: Light | Medium | Heavy. Bonus/Curse columns: which stat is affected. bonus_stat_mod and curse_stat_mod: value per piece equipped.
A2: id | B2: name | C2: weight_class | D2: bonus_stat | E2: bonus_stat_mod | F2: curse_stat | G2: curse_stat_mod | H2: min_test_level | I2: notes | J2: _JSON_KEY
A3: 0 | B3: Berserker | C3: Heavy | D3: PATK | F3: PDEF | J3: gear_sets
A4: 1 | B4: Phantom | C4: Medium | D4: PEVA | F4: MEVA | J4: gear_sets
A5: 2 | B5: Sentinel | C5: Heavy | D5: PHIT | F5: MHIT | J5: gear_sets
A6: 3 | B6: Warden | C6: Heavy | D6: PDEF | F6: PATK | J6: gear_sets
A7: 4 | B7: Glacier | C7: Light | D7: WTR | F7: FIR | J7: gear_sets
A8: 5 | B8: Storm | C8: Light | D8: MATK | F8: PATK | J8: gear_sets
A9: 6 | B9: Viper | C9: Medium | D9: PATK | F9: MATK | J9: gear_sets
A10: 7 | B10: Trickster | C10: Medium | D10: MEVA | F10: MHIT | J10: gear_sets

Sheet GearSet_Bonuses
A1: Calculated set bonuses per piece count. set_id links to GearSets. pieces_equipped: 2–6. bonus and curse values are total (pieces × per-piece rate).
A2: id | B2: set_id | C2: set_name | D2: pieces_equipped | E2: bonus_total | F2: curse_total | G2: notes
A3: 0 | B3: 0 | C3: Berserker | D3: 2 | E3: =5*2 -> 10 | F3: =-3*2 -> -6
A4: 1 | B4: 0 | C4: Berserker | D4: 3 | E4: =5*3 -> 15 | F4: =-3*3 -> -9
A5: 2 | B5: 0 | C5: Berserker | D5: 4 | E5: =5*4 -> 20 | F5: =-3*4 -> -12
A6: 3 | B6: 0 | C6: Berserker | D6: 5 | E6: =5*5 -> 25 | F6: =-3*5 -> -15
A7: 4 | B7: 0 | C7: Berserker | D7: 6 | E7: =5*6 -> 30 | F7: =-3*6 -> -18
A8: 5 | B8: 1 | C8: Phantom | D8: 2 | E8: =1.05*2 -> 2.1 | F8: =-1.5*2 -> -3
A9: 6 | B9: 1 | C9: Phantom | D9: 3 | E9: =1.05*3 -> 3.15 | F9: =-1.5*3 -> -4.5
A10: 7 | B10: 1 | C10: Phantom | D10: 4 | E10: =1.05*4 -> 4.2 | F10: =-1.5*4 -> -6
A11: 8 | B11: 1 | C11: Phantom | D11: 5 | E11: =1.05*5 -> 5.25 | F11: =-1.5*5 -> -7.5
A12: 9 | B12: 1 | C12: Phantom | D12: 6 | E12: =1.05*6 -> 6.3 | F12: =-1.5*6 -> -9
A13: 10 | B13: 2 | C13: Sentinel | D13: 2 | E13: =5*2 -> 10 | F13: =-3*2 -> -6
A14: 11 | B14: 2 | C14: Sentinel | D14: 3 | E14: =5*3 -> 15 | F14: =-3*3 -> -9
A15: 12 | B15: 2 | C15: Sentinel | D15: 4 | E15: =5*4 -> 20 | F15: =-3*4 -> -12
A16: 13 | B16: 2 | C16: Sentinel | D16: 5 | E16: =5*5 -> 25 | F16: =-3*5 -> -15
A17: 14 | B17: 2 | C17: Sentinel | D17: 6 | E17: =5*6 -> 30 | F17: =-3*6 -> -18
A18: 15 | B18: 3 | C18: Warden | D18: 2 | E18: =1.05*2 -> 2.1 | F18: =-1.5*2 -> -3
A19: 16 | B19: 3 | C19: Warden | D19: 3 | E19: =1.05*3 -> 3.15 | F19: =-1.5*3 -> -4.5
A20: 17 | B20: 3 | C20: Warden | D20: 4 | E20: =1.05*4 -> 4.2 | F20: =-1.5*4 -> -6
A21: 18 | B21: 3 | C21: Warden | D21: 5 | E21: =1.05*5 -> 5.25 | F21: =-1.5*5 -> -7.5
A22: 19 | B22: 3 | C22: Warden | D22: 6 | E22: =1.05*6 -> 6.3 | F22: =-1.5*6 -> -9
A23: 20 | B23: 4 | C23: Glacier | D23: 2 | E23: =5*2 -> 10 | F23: =-3*2 -> -6
A24: 21 | B24: 4 | C24: Glacier | D24: 3 | E24: =5*3 -> 15 | F24: =-3*3 -> -9
A25: 22 | B25: 4 | C25: Glacier | D25: 4 | E25: =5*4 -> 20 | F25: =-3*4 -> -12
A26: 23 | B26: 4 | C26: Glacier | D26: 5 | E26: =5*5 -> 25 | F26: =-3*5 -> -15
A27: 24 | B27: 4 | C27: Glacier | D27: 6 | E27: =5*6 -> 30 | F27: =-3*6 -> -18
A28: 25 | B28: 5 | C28: Storm | D28: 2 | E28: =1.05*2 -> 2.1 | F28: =-1.5*2 -> -3
A29: 26 | B29: 5 | C29: Storm | D29: 3 | E29: =1.05*3 -> 3.15 | F29: =-1.5*3 -> -4.5
A30: 27 | B30: 5 | C30: Storm | D30: 4 | E30: =1.05*4 -> 4.2 | F30: =-1.5*4 -> -6
A31: 28 | B31: 5 | C31: Storm | D31: 5 | E31: =1.05*5 -> 5.25 | F31: =-1.5*5 -> -7.5
A32: 29 | B32: 5 | C32: Storm | D32: 6 | E32: =1.05*6 -> 6.3 | F32: =-1.5*6 -> -9
A33: 30 | B33: 6 | C33: Viper | D33: 2 | E33: =5*2 -> 10 | F33: =-3*2 -> -6
A34: 31 | B34: 6 | C34: Viper | D34: 3 | E34: =5*3 -> 15 | F34: =-3*3 -> -9
A35: 32 | B35: 6 | C35: Viper | D35: 4 | E35: =5*4 -> 20 | F35: =-3*4 -> -12
A36: 33 | B36: 6 | C36: Viper | D36: 5 | E36: =5*5 -> 25 | F36: =-3*5 -> -15
A37: 34 | B37: 6 | C37: Viper | D37: 6 | E37: =5*6 -> 30 | F37: =-3*6 -> -18
A38: 35 | B38: 7 | C38: Trickster | D38: 2 | E38: =1.05*2 -> 2.1 | F38: =-1.5*2 -> -3
A39: 36 | B39: 7 | C39: Trickster | D39: 3 | E39: =1.05*3 -> 3.15 | F39: =-1.5*3 -> -4.5
A40: 37 | B40: 7 | C40: Trickster | D40: 4 | E40: =1.05*4 -> 4.2 | F40: =-1.5*4 -> -6
...

Sheet CombatLevelFormula
A1: Combat level is derived from total CP earned from investing in skill boxes. This sheet defines the formula constants. Claude Code uses these to compute a player's effective combat level from their Combat Points totals..
A2: id | B2: parameter | C2: value | D2: notes | E2: example | F2: _JSON_KEY
A3: 0 | B3: cp_per_combat_level | C3: 25 | D3: 25 CP = +1 combat level. CP gained from Skill Boxes. | E3: 180 CP earned → combat level 7 | F3: combat_level_formula
A4: 1 | B4: base_combat_level | C4: 1 | D4: Everyone starts at combat level 1 | E4: Novice base skills net 25 CP → level 1 | F4: combat_level_formula
A5: 2 | B5: unlearn_sp_refund_rate | C5: 1 | D5: Fraction of LP refunded on unlearn (1.0 = full refund) | E5: Unlearn a 30 LP box → get 30 LP back | F5: combat_level_formula
A6: 3 | B6: unlearn_removes_stat_bonuses | C6: true | D6: Stat bonuses from the box are removed on unlearn | E6: Unlearn Iron Body → lose its HP and DEF | F6: combat_level_formula
A7: 4 | B7: unlearn_removes_skills | C7: true | D7: Skills from the unlearned box are removed from the player | E7: Unlearn Shadow Step → lose Shadow Step skill | F7: combat_level_formula
